<?xml version="1.0" encoding="utf-8"?>
<!-- This URDF was automatically created by SolidWorks to URDF Exporter! Originally created by Stephen Brawner (brawner@gmail.com) 
     Commit Version: 1.6.0-4-g7f85cfe  Build Version: 1.6.7995.38578
     For more information, please see http://wiki.ros.org/sw_urdf_exporter -->
<robot
  name="bi_urdf">
  <mujoco>
  <compiler
    meshdir="/home/csl/mujoco_rl/crazydog_mujoco/bi_urdf/meshes"
    balanceinertia="true"
    discardvisual="false" />
  </mujoco>
  <link
    name="base">
    <inertial>
      <origin
        xyz="-0.02790197 0.00038374 -0.08713367"
        rpy="0 0 0" />
      <mass
        value="3.74400000" />
      <inertia
        ixx="0.01794711"
        ixy="0.00007467"
        ixz="-0.00221989"
        iyy="0.02602695"
        iyz="-0.00017139"
        izz="0.02385452" />
    </inertial>
    <visual>
      <origin
        xyz="0 0 0"
        rpy="0 0 0" />
      <geometry>
        <mesh
          filename="package://bi_urdf/meshes/Base.STL" />
      </geometry>
      <material
        name="">
        <color
          rgba="0.752941176470588 0.752941176470588 0.752941176470588 1" />
      </material>
    </visual>
    <collision>
      <origin
        xyz="0 0 0"
        rpy="0 0 0" />
      <geometry>
        <mesh
          filename="package://bi_urdf/meshes/Base.STL" />
      </geometry>
    </collision>
  </link>
  <link
    name="L_hip">
    <inertial>
      <origin
        xyz="-0.00437791 -0.00083480 -0.00000156"
        rpy="0 0 0" />
      <mass
        value="0.57300000" />
      <inertia
        ixx="0.00035684"
        ixy="0.00000082"
        ixz="-0.00000003"
        iyy="0.00066067"
        iyz="0.000000001"
        izz="0.00042648" />
    </inertial>
    <visual>
      <origin
        xyz="0 0 0"
        rpy="0 0 0" />
      <geometry>
        <mesh
          filename="package://bi_urdf/meshes/L_hip.STL" />
      </geometry>
      <material
        name="">
        <color
          rgba="0.752941176470588 0.752941176470588 0.752941176470588 1" />
      </material>
    </visual>
    <collision>
      <origin
        xyz="0 0 0"
        rpy="0 0 0" />
      <geometry>
        <mesh
          filename="package://bi_urdf/meshes/L_hip.STL" />
      </geometry>
    </collision>
  </link>
  <joint
    name="L_hip_joint"
    type="revolute">
    <origin
      xyz="0 0.05624988744529 -0.0547749999999975"
      rpy="0 0 0" />
    <parent
      link="base" />
    <child
      link="L_hip" />
    <axis
      xyz="1 0 0" />
  </joint>
  <link
    name="L_thigh">
    <inertial>
      <origin
        xyz="-0.00000319 0.05414817 -0.03014960"
        rpy="0 0 0" />
      <mass
        value="1.12300000" />
      <inertia
        ixx="0.00499319"
        ixy="-0.00000083"
        ixz="0.00000077"
        iyy="0.00498415"
        iyz="-0.00069204"
        izz="0.00115921" />
    </inertial>
    <visual>
      <origin
        xyz="0 0 0"
        rpy="0 0 0" />
      <geometry>
        <mesh
          filename="package://bi_urdf/meshes/L_thigh.STL" />
      </geometry>
      <material
        name="">
        <color
          rgba="0.752941176470588 0.752941176470588 0.752941176470588 1" />
      </material>
    </visual>
    <collision>
      <origin
        xyz="0 0 0"
        rpy="0 0 0" />
      <geometry>
        <mesh
          filename="package://bi_urdf/meshes/L_thigh.STL" />
      </geometry>
    </collision>
  </link>
  <joint
    name="L_thigh_joint"
    type="revolute">
    <origin
      xyz="-0.000265036093632373 0.0144424855132426 0"
      rpy="0 0 0" />
    <parent
      link="L_hip" />
    <child
      link="L_thigh" />
    <axis
      xyz="0 1 0" />
  </joint>
  <link
    name="L_calf">
    <inertial>
      <origin
        xyz="0.00002300 0.02974174 -0.15275547"
        rpy="0 0 0" />
      <mass
        value="0.55500000" />
      <inertia
        ixx="0.00382006"
        ixy="-0.00000009"
        ixz="0.00000185"
        iyy="0.00386186"
        iyz="-0.00023167"
        izz="0.00022552" />
    </inertial>
    <visual>
      <origin
        xyz="0 0 0"
        rpy="0 0 0" />
      <geometry>
        <mesh
          filename="package://bi_urdf/meshes/L_calf.STL" />
      </geometry>
      <material
        name="">
        <color
          rgba="0.792156862745098 0.819607843137255 0.933333333333333 1" />
      </material>
    </visual>
    <collision>
      <origin
        xyz="0 0 0"
        rpy="0 0 0" />
      <geometry>
        <mesh
          filename="package://bi_urdf/meshes/L_calf.STL" />
      </geometry>
    </collision>
  </link>
  <joint
    name="L_calf_joint"
    type="revolute">
    <origin
      xyz="0 0.0527575781855786 -0.215000000000008"
      rpy="0 0 0" />
    <parent
      link="L_thigh" />
    <child
      link="L_calf" />
    <axis
      xyz="0 1 0" />
  </joint>
  <link
    name="L_wheel">
    <inertial>
      <origin
        xyz="0.00000000 0.01519770 0.00000000"
        rpy="0 0 0" />
      <mass
        value="0.28000000" />
      <inertia
        ixx="0.00045838"
        ixy="0.000000001"
        ixz="0.000000001"
        iyy="0.00088385"
        iyz="0.000000001"
        izz="0.00045837" />
    </inertial>
    <visual>
      <origin
        xyz="0 0 0"
        rpy="0 0 0" />
      <geometry>
        <mesh
          filename="package://bi_urdf/meshes/L_wheel.STL" />
      </geometry>
      <material
        name="">
        <color
          rgba="0.792156862745098 0.819607843137255 0.933333333333333 1" />
      </material>
    </visual>
    <collision>
      <origin
        xyz="0 0 0"
        rpy="0 0 0" />
      <geometry>
        <mesh
          filename="package://bi_urdf/meshes/L_wheel.STL" />
      </geometry>
    </collision>
  </link>
  <joint
    name="L_wheel_joint"
    type="revolute">
    <origin
      xyz="0 0.0372306801421307 -0.215"
      rpy="0 0 0" />
    <parent
      link="L_calf" />
    <child
      link="L_wheel" />
    <axis
      xyz="0 1 0" />
  </joint>
  <link
    name="R_hip">
    <inertial>
      <origin
        xyz="-0.00411048 0.00527723 0.00000000"
        rpy="0 0 0" />
      <mass
        value="0.57300000" />
      <inertia
        ixx="0.00035682"
        ixy="-0.00000082"
        ixz="-0.00000002"
        iyy="0.00066070"
        iyz="0.000000001"
        izz="0.00042653" />
    </inertial>
    <visual>
      <origin
        xyz="0 0 0"
        rpy="0 0 0" />
      <geometry>
        <mesh
          filename="package://bi_urdf/meshes/R_hip.STL" />
      </geometry>
      <material
        name="">
        <color
          rgba="0.752941176470588 0.752941176470588 0.752941176470588 1" />
      </material>
    </visual>
    <collision>
      <origin
        xyz="0 0 0"
        rpy="0 0 0" />
      <geometry>
        <mesh
          filename="package://bi_urdf/meshes/R_hip.STL" />
      </geometry>
    </collision>
  </link>
  <joint
    name="R_hip_joint"
    type="revolute">
    <origin
      xyz="-0.000265036093632404 -0.060692372958567 -0.054775543466975"
      rpy="0 0 0" />
    <parent
      link="base" />
    <child
      link="R_hip" />
    <axis
      xyz="1 0 0" />
  </joint>
  <link
    name="R_thigh">
    <inertial>
      <origin
        xyz="-0.00000455 -0.05414885 -0.03014968"
        rpy="0 0 0" />
      <mass
        value="1.12300000" />
      <inertia
        ixx="0.00499324"
        ixy="0.00000080"
        ixz="0.00000079"
        iyy="0.00498427"
        iyz="0.00069204"
        izz="0.00115923" />
    </inertial>
    <visual>
      <origin
        xyz="0 0 0"
        rpy="0 0 0" />
      <geometry>
        <mesh
          filename="package://bi_urdf/meshes/R_thigh.STL" />
      </geometry>
      <material
        name="">
        <color
          rgba="0.752941176470588 0.752941176470588 0.752941176470588 1" />
      </material>
    </visual>
    <collision>
      <origin
        xyz="0 0 0"
        rpy="0 0 0" />
      <geometry>
        <mesh
          filename="package://bi_urdf/meshes/R_thigh.STL" />
      </geometry>
    </collision>
  </link>
  <joint
    name="R_thigh_joint"
    type="revolute">
    <origin
      xyz="0 -0.01 0"
      rpy="0 0 0" />
    <parent
      link="R_hip" />
    <child
      link="R_thigh" />
    <axis
      xyz="0 1 0" />
  </joint>
  <link
    name="R_calf">
    <inertial>
      <origin
        xyz="0.00002256 -0.02974209 -0.15275385"
        rpy="0 0 0" />
      <mass
        value="0.55500000" />
      <inertia
        ixx="0.00382014"
        ixy="0.00000009"
        ixz="0.00000188"
        iyy="0.00386193"
        iyz="0.00023168"
        izz="0.00022552" />
    </inertial>
    <visual>
      <origin
        xyz="0 0 0"
        rpy="0 0 0" />
      <geometry>
        <mesh
          filename="package://bi_urdf/meshes/R_calf.STL" />
      </geometry>
      <material
        name="">
        <color
          rgba="0.792156862745098 0.819607843137255 0.933333333333333 1" />
      </material>
    </visual>
    <collision>
      <origin
        xyz="0 0 0"
        rpy="0 0 0" />
      <geometry>
        <mesh
          filename="package://bi_urdf/meshes/R_calf.STL" />
      </geometry>
    </collision>
  </link>
  <joint
    name="R_calf_joint"
    type="revolute">
    <origin
      xyz="0 -0.0527575781855423 -0.215000000000002"
      rpy="0 0 0" />
    <parent
      link="R_thigh" />
    <child
      link="R_calf" />
    <axis
      xyz="0 1 0" />
  </joint>
  <link
    name="R_wheel">
    <inertial>
      <origin
        xyz="0.00000000 -0.01519770 0.00000000"
        rpy="0 0 0" />
      <mass
        value="0.28000000" />
      <inertia
        ixx="0.00045838"
        ixy="0.000000001"
        ixz="0.000000001"
        iyy="0.00088386"
        iyz="0.000000001"
        izz="0.00045838" />
    </inertial>
    <visual>
      <origin
        xyz="0 0 0"
        rpy="0 0 0" />
      <geometry>
        <mesh
          filename="package://bi_urdf/meshes/R_wheel.STL" />
      </geometry>
      <material
        name="">
        <color
          rgba="0.792156862745098 0.819607843137255 0.933333333333333 1" />
      </material>
    </visual>
    <collision>
      <origin
        xyz="0 0 0"
        rpy="0 0 0" />
      <geometry>
        <mesh
          filename="package://bi_urdf/meshes/R_wheel.STL" />
      </geometry>
    </collision>
  </link>
  <joint
    name="R_wheel_joint"
    type="revolute">
    <origin
      xyz="0 -0.0372306801421371 -0.215"
      rpy="0 0 0" />
    <parent
      link="R_calf" />
    <child
      link="R_wheel" />
    <axis
      xyz="0 1 0" />
  </joint>
</robot>
