<mujoco model="bi_urdf">
  <compiler angle="radian" meshdir="/home/csl/robot_model/bi_urdf/meshes/"/>
  <size njmax="500" nconmax="100" />

  <option cone="elliptic" impratio="100" />

  <default>
      <default class="crazydog">
          <geom friction="0.4" margin="0.001" condim="1"/>
          <joint axis="0 1 0" damping="0.1" armature="0.01" frictionloss="0.2"/>
          <motor ctrlrange="-23.7 23.7"/>
          <default class="visual">
              <geom type="mesh" contype="0" conaffinity="0" group="2"/>
          </default>
          <default class="collision">
              <geom group="3"/>
              <default class="foot">
              <geom size="0.022"  priority="1" condim="6"
                  friction="0.4 0.02 0.01"/>
              </default>
          </default>
      </default>
  </default>
  <asset>
    <mesh name="base_link" file="base_link.STL"/>
    <mesh name="orin_Link" file="orin_Link.STL"/>
    <mesh name="bat_Link" file="bat_Link.STL"/>
    <mesh name="r_Link" file="r_Link.STL"/>
    <mesh name="rr_Link" file="rr_Link.STL"/>
    <mesh name="rrr_Link" file="rrr_Link.STL"/>
    <mesh name="ru_Link" file="ru_Link.STL"/>
    <mesh name="rd_Link" file="rd_Link.STL"/>
    <mesh name="rw_Link" file="rw_Link.STL"/>
    <mesh name="l_Link" file="l_Link.STL"/>
    <mesh name="ll_Link" file="ll_Link.STL"/>
    <mesh name="lll_Link" file="lll_Link.STL"/>
    <mesh name="lu_Link" file="lu_Link.STL"/>
    <mesh name="ld_Link" file="ld_Link.STL"/>
    <mesh name="lw_Link" file="lw_Link.STL"/>
  </asset>

  <worldbody>
    <body name="base_link" pos="0 0 0" childclass="crazydog">
      <inertial pos="0.01096 0.00049 -0.08447" quat="1 0 0 0" mass="1.7" diaginertia="0.01982751490 0.02421281189 0.0108854248"/>
      <freejoint />
      <site name="imu" pos="0 0 0" />
      <geom type="mesh" contype="0" conaffinity="0" group="1" density="0" rgba="1 0 0 1" mesh="base_link"/>
      <geom type="mesh" rgba="1 0 0 1" mesh="base_link"/>
      <body name="orin_Link">
        <inertial pos="-0.11589 -0.00301 -0.06043" quat="1 0 0 0" mass="0.3" diaginertia="0.00166804201 0.00544430491 0.00436559892"/>
        <geom pos="-0.0918148 -0.0249 -0.117725" quat="1 0 0 0" type="mesh" contype="0" conaffinity="0" group="1" density="0" rgba="0.2 0.2 0.2 1" mesh="orin_Link"/>
        <geom pos="-0.0918148 -0.0249 -0.117725" quat="1 0 0 0" type="mesh" rgba="0.2 0.2 0.2 1" mesh="orin_Link"/>
      </body>
      <body name="bat_Link">
        <inertial pos="-0.01301 0.00224 -0.15741" quat="1 0 0 0" mass="0.672" diaginertia="0.01716082946 0.0179077777 0.0015612673"/>
        <geom pos="-0.0416148 0 -0.179925" quat="1 0 0 0" type="mesh" contype="0" conaffinity="0" group="1" density="0" rgba="0.2 0.2 0.2 1" mesh="bat_Link"/>
        <geom pos="-0.0416148 0 -0.179925" quat="1 0 0 0" type="mesh" rgba="0.2 0.2 0.2 1" mesh="bat_Link"/>
      </body>
      <body name="r_Link">
        <inertial pos="-0.07425 -0.05625 -0.05478" quat="1 0 0 0" mass="0.536" diaginertia="0.00385840237 0.0049011775 0.00497878575"/>
        <geom pos="-0.0535148 -0.05625 -0.0547753" type="mesh" contype="0" conaffinity="0" group="1" density="0" rgba="1 1 0 1" mesh="r_Link"/>
        <geom pos="-0.0535148 -0.05625 -0.0547753" type="mesh" rgba="1 1 0 1" mesh="r_Link"/>
        <body name="rr_Link">
          <inertial pos="-0.00438 -0.05542 -0.05478" quat="1 0 0 0" mass="0.573" diaginertia="0.00383568778 0.00239093643 0.00219709425"/>
          <geom pos="-0.0535148 -0.05625 -0.0547753" quat="1 0 0 0" type="mesh" contype="0" conaffinity="0" group="1" density="0" rgba="0 1 0 1" mesh="rr_Link"/>
          <geom pos="-0.0535148 -0.05625 -0.0547753" quat="1 0 0 0" type="mesh" rgba="0 1 0 1" mesh="rr_Link"/>
          <body name="rrr_Link">
            <inertial pos="-0.00024 -0.10799 -0.05471" quat="1 0 0 0" mass="0.614" diaginertia="0.00945726496 0.00249493205 0.00764470258"/>
            <geom pos="-0.000265036 -0.0706925 -0.0547753" quat="1 0 0 0" type="mesh" contype="0" conaffinity="0" group="1" density="0" rgba="0 1 1 1" mesh="rrr_Link"/>
            <geom pos="-0.000265036 -0.0706925 -0.0547753" quat="1 0 0 0" type="mesh" rgba="0 1 1 1" mesh="rrr_Link"/>
            <body name="ru_Link">
              <inertial pos="-0.00031 -0.14157 -0.12137" quat="1 0 0 0" mass="0.509" diaginertia="0.02061237381 0.01058887989 0.0104915547"/>
              <geom pos="-0.000265036 -0.1284 -0.0547753" quat="0.820664 0 0.571411 0" type="mesh" contype="0" conaffinity="0" group="1" density="0" rgba="0 0 1 1" mesh="ru_Link"/>
              <geom pos="-0.000265036 -0.1284 -0.0547753" quat="0.820664 0 0.571411 0" type="mesh" rgba="0 0 1 1" mesh="ru_Link"/>
              <body name="rd_Link">
                <inertial pos="-0.00031 -0.14157 -0.12137" quat="1 0 0 0" mass="0.555" diaginertia="0.11532470912 0.10294684138 0.01264523627"/>
                <geom pos="-0.201908 -0.1284 -0.129376" quat="0.895306 0 -0.445451 0" type="mesh" contype="0" conaffinity="0" group="1" density="0" rgba="0.792157 0.819608 0.933333 1" mesh="rd_Link"/>
                <geom pos="-0.201908 -0.1284 -0.129376" quat="0.895306 0 -0.445451 0" type="mesh" rgba="0.792157 0.819608 0.933333 1" mesh="rd_Link"/>
                <body name="rw_Link" pos="-0.0304171 -0.157081 -0.259052" quat="0.895306 0 -0.445451 0">
                  <inertial pos="-0.00027 -0.17228 -0.48478" quat="0.718647 0.123094 -0.115814 0.674523" mass="0.28" diaginertia="0.0749504 0.0745693 0.000505852"/>
                  <joint name="R_calf2wheel" pos="0 0 0" axis="0 1 0"/>
                  <geom type="mesh" contype="0" conaffinity="0" group="1" density="0" rgba="0.2 0.2 0.2 1" mesh="rw_Link"/>
                  <geom type="mesh" rgba="0.2 0.2 0.2 1" mesh="rw_Link" class="foot"/>
                </body>
              </body>
            </body>
          </body>
        </body>
      </body>
      <body name="l_Link">
        <inertial pos="-0.07425 0.05625 -0.05478" quat="1 0 0 0" mass="0.536" diaginertia="0.00385839628 0.00490116608 0.00497879081"/>
        <geom pos="-0.0535148 0.05625 -0.0547753" type="mesh" contype="0" conaffinity="0" group="1" density="0" rgba="1 1 0 1" mesh="l_Link"/>
        <geom pos="-0.0535148 0.05625 -0.0547753" type="mesh" rgba="1 1 0 1" mesh="l_Link"/>
        <body name="ll_Link">
          <inertial pos="-0.00438 0.05542 -0.05478" quat="1 0 0 0" mass="0.573" diaginertia="0.00383572240 0.00239093628 0.00219705608"/>
          <geom pos="-0.0535148 0.05625 -0.0547753" quat="1 0 0 0" type="mesh" contype="0" conaffinity="0" group="1" density="0" rgba="0 1 0 1" mesh="ll_Link"/>
          <geom pos="-0.0535148 0.05625 -0.0547753" quat="1 0 0 0" type="mesh" rgba="0 1 0 1" mesh="ll_Link"/>
          <body name="lll_Link">
            <inertial pos="-0.00023 0.10799 -0.05471" quat="1 0 0 0" mass="0.614" diaginertia="0.00945717399 0.00249493047 0.00764450217"/>
            <geom pos="-0.000265036 0.0706925 -0.0547753" quat="1 0 0 0" type="mesh" contype="0" conaffinity="0" group="1" density="0" rgba="0 1 1 1" mesh="lll_Link"/>
            <geom pos="-0.000265036 0.0706925 -0.0547753" quat="1 0 0 0" type="mesh" rgba="0 1 1 1" mesh="lll_Link"/>
            <body name="lu_Link">
              <inertial pos="-0.00031 0.14157 -0.12137" quat="1 0 0 0" mass="0.509" diaginertia="0.02061220484 0.01058873621 0.01049154602"/>
              <geom pos="-0.000265036 0.1284 -0.0547753" quat="0.820664 0 0.571411 0" type="mesh" contype="0" conaffinity="0" group="1" density="0" rgba="0 0 1 1" mesh="lu_Link"/>
              <geom pos="-0.000265036 0.1284 -0.0547753" quat="0.820664 0 0.571411 0" type="mesh" rgba="0 0 1 1" mesh="lu_Link"/>
              <body name="ld_Link">
                <inertial pos="-0.00024 0.14959 -0.42253" quat="1 0 0 0" mass="0.555" diaginertia="0.11532533580 0.10294753695 0.01264518379"/>
                <geom pos="-0.201908 0.1284 -0.129376" quat="0.895306 0 -0.445451 0" type="mesh" contype="0" conaffinity="0" group="1" density="0" rgba="0.792157 0.819608 0.933333 1" mesh="ld_Link"/>
                <geom pos="-0.201908 0.1284 -0.129376" quat="0.895306 0 -0.445451 0" type="mesh" rgba="0.792157 0.819608 0.933333 1" mesh="ld_Link"/>
                <body name="lw_Link" pos="-0.0304171 0.157081 -0.259052" quat="0.895306 0 -0.445451 0">
                  <inertial pos="-0.00027 0.17228 -0.48478" quat="0.674522 -0.115814 0.123094 0.718648" mass="0.28" diaginertia="0.0749504 0.0745693 0.000505847"/>
                  <joint name="L_calf2wheel" pos="0 0 0" axis="0 1 0"/>
                  <geom type="mesh" contype="0" conaffinity="0" group="1" density="0" rgba="0.2 0.2 0.2 1" mesh="lw_Link"/>
                  <geom type="mesh" rgba="0.2 0.2 0.2 1" mesh="lw_Link" class="foot"/>
                </body>
              </body>
            </body>
          </body>
        </body>
      </body>
    </body>
  </worldbody>

  <actuator>
        <motor ctrlrange="-15 15" name="R_wheel" joint="R_calf2wheel" />
        <motor ctrlrange="-15 15" name="L_wheel" joint="L_calf2wheel" />
  </actuator>

  <sensor>
      <jointpos name="R_wheel_pos" joint="R_calf2wheel" />
      <jointpos name="L_wheel_pos" joint="L_calf2wheel" />

      <jointvel name="R_wheel_vel" joint="R_calf2wheel" noise="0.0"/>
      <jointvel name="L_wheel_vel" joint="L_calf2wheel" noise="0.0"/>

      <jointactuatorfrc name="R_wheel_torque" joint="R_calf2wheel" />
      <jointactuatorfrc name="F_wheel_torque" joint="L_calf2wheel" />

      <framequat name="imu_quat" objtype="site" objname="imu" noise="0.0"/>
      <gyro name="imu_gyro" site="imu" noise="0.0"/>
      <accelerometer name="imu_acc" site="imu" />

      <framepos name="frame_pos" objtype="site" objname="imu" />
      <framelinvel name="frame_lin_vel" objtype="site" objname="imu" />
      <frameangvel name="frame_ang_vel" objtype="site" objname="imu" />
  </sensor>
</mujoco>
